Warning: no access to tty (Bad file descriptor).
Thus no job control in this shell.
/home1/datahome/xyu/.miniconda3/envs/equinox/lib/python3.6/site-packages/distributed/utils.py:128: RuntimeWarning: Couldn't detect a suitable IP address for reaching '8.8.8.8', defaulting to '127.0.0.1': [Errno 101] Network is unreachable
  % (host, default, e), RuntimeWarning)
distributed.nanny - INFO -         Start Nanny at: 'tcp://10.148.0.144:42328'
distributed.nanny - INFO -         Start Nanny at: 'tcp://10.148.0.144:47770'
/home1/datahome/xyu/.miniconda3/envs/equinox/lib/python3.6/site-packages/distributed/utils.py:128: RuntimeWarning: Couldn't detect a suitable IP address for reaching '8.8.8.8', defaulting to '127.0.0.1': [Errno 101] Network is unreachable
  % (host, default, e), RuntimeWarning)
distributed.worker - INFO -       Start worker at:   tcp://10.148.0.144:34313
distributed.worker - INFO -          Listening to:   tcp://10.148.0.144:34313
distributed.worker - INFO -              nanny at:         10.148.0.144:47770
distributed.worker - INFO -              bokeh at:          10.148.0.144:8789
distributed.worker - INFO - Waiting to connect to:    tcp://10.148.1.29:46726
distributed.worker - INFO - -------------------------------------------------
/home1/datahome/xyu/.miniconda3/envs/equinox/lib/python3.6/site-packages/distributed/utils.py:128: RuntimeWarning: Couldn't detect a suitable IP address for reaching '8.8.8.8', defaulting to '127.0.0.1': [Errno 101] Network is unreachable
  % (host, default, e), RuntimeWarning)
distributed.worker - INFO -       Start worker at:   tcp://10.148.0.144:44170
distributed.worker - INFO -          Listening to:   tcp://10.148.0.144:44170
distributed.worker - INFO -              nanny at:         10.148.0.144:42328
distributed.worker - INFO -              bokeh at:         10.148.0.144:43642
distributed.worker - INFO -               Threads:                          4
distributed.worker - INFO - Waiting to connect to:    tcp://10.148.1.29:46726
distributed.worker - INFO - -------------------------------------------------
distributed.worker - INFO -                Memory:                   50.00 GB
distributed.worker - INFO -       Local Directory: /dev/shm/pbs.2974443.datarmor0/worker-pu97heqk
distributed.worker - INFO - -------------------------------------------------
distributed.worker - INFO -               Threads:                          4
distributed.worker - INFO -                Memory:                   50.00 GB
distributed.worker - INFO -       Local Directory: /dev/shm/pbs.2974443.datarmor0/worker-joi2bwsa
distributed.worker - INFO - -------------------------------------------------
distributed.worker - INFO -         Registered to:    tcp://10.148.1.29:46726
distributed.worker - INFO - -------------------------------------------------
distributed.core - INFO - Starting established connection
distributed.worker - INFO -         Registered to:    tcp://10.148.1.29:46726
distributed.worker - INFO - -------------------------------------------------
distributed.core - INFO - Starting established connection
distributed.worker - WARNING -  Compute Failed
Function:  _enforce_dtype
args:      (False, False)
kwargs:    {'enforce_dtype': dtype('bool'), 'enforce_dtype_function': <built-in function and_>}
Exception: AttributeError("'bool' object has no attribute 'dtype'",)

distributed.worker - INFO - Stopping worker at tcp://10.148.0.144:44170
distributed.worker - INFO - Stopping worker at tcp://10.148.0.144:34313
distributed.worker - INFO - Connection to scheduler broken.  Reconnecting...
distributed.worker - INFO - -------------------------------------------------
distributed.worker - INFO - Connection to scheduler broken.  Reconnecting...
distributed.worker - INFO - -------------------------------------------------
distributed.nanny - INFO - Closing Nanny at 'tcp://10.148.0.144:47770'
distributed.nanny - INFO - Closing Nanny at 'tcp://10.148.0.144:42328'
distributed.dask_worker - INFO - End worker
/home1/datahome/xyu/.miniconda3/envs/equinox/lib/python3.6/site-packages/distributed/utils.py:128: RuntimeWarning: Couldn't detect a suitable IP address for reaching '8.8.8.8', defaulting to '127.0.0.1': [Errno 101] Network is unreachable
  % (host, default, e), RuntimeWarning)
