Warning: no access to tty (Bad file descriptor).
Thus no job control in this shell.
/home1/datahome/xyu/.miniconda3/envs/equinox/lib/python3.6/site-packages/distributed/utils.py:128: RuntimeWarning: Couldn't detect a suitable IP address for reaching '8.8.8.8', defaulting to '127.0.0.1': [Errno 101] Network is unreachable
  % (host, default, e), RuntimeWarning)
distributed.nanny - INFO -         Start Nanny at: 'tcp://10.148.0.199:33773'
distributed.nanny - INFO -         Start Nanny at: 'tcp://10.148.0.199:41876'
/home1/datahome/xyu/.miniconda3/envs/equinox/lib/python3.6/site-packages/distributed/utils.py:128: RuntimeWarning: Couldn't detect a suitable IP address for reaching '8.8.8.8', defaulting to '127.0.0.1': [Errno 101] Network is unreachable
  % (host, default, e), RuntimeWarning)
distributed.worker - INFO -       Start worker at:   tcp://10.148.0.199:60457
distributed.worker - INFO -          Listening to:   tcp://10.148.0.199:60457
distributed.worker - INFO -              nanny at:         10.148.0.199:33773
distributed.worker - INFO -              bokeh at:          10.148.0.199:8789
distributed.worker - INFO - Waiting to connect to:     tcp://10.148.1.2:35178
distributed.worker - INFO - -------------------------------------------------
/home1/datahome/xyu/.miniconda3/envs/equinox/lib/python3.6/site-packages/distributed/utils.py:128: RuntimeWarning: Couldn't detect a suitable IP address for reaching '8.8.8.8', defaulting to '127.0.0.1': [Errno 101] Network is unreachable
  % (host, default, e), RuntimeWarning)
distributed.worker - INFO -       Start worker at:   tcp://10.148.0.199:49758
distributed.worker - INFO -          Listening to:   tcp://10.148.0.199:49758
distributed.worker - INFO -              nanny at:         10.148.0.199:41876
distributed.worker - INFO -              bokeh at:         10.148.0.199:45855
distributed.worker - INFO - Waiting to connect to:     tcp://10.148.1.2:35178
distributed.worker - INFO - -------------------------------------------------
distributed.worker - INFO -               Threads:                          4
distributed.worker - INFO -                Memory:                   50.00 GB
distributed.worker - INFO -       Local Directory: /dev/shm/pbs.1346232.datarmor0/worker-8e74c3lp
distributed.worker - INFO - -------------------------------------------------
distributed.worker - INFO -               Threads:                          4
distributed.worker - INFO -                Memory:                   50.00 GB
distributed.worker - INFO -       Local Directory: /dev/shm/pbs.1346232.datarmor0/worker-vm7x47sh
distributed.worker - INFO - -------------------------------------------------
distributed.worker - INFO -         Registered to:     tcp://10.148.1.2:35178
distributed.worker - INFO - -------------------------------------------------
distributed.core - INFO - Starting established connection
distributed.worker - INFO -         Registered to:     tcp://10.148.1.2:35178
distributed.worker - INFO - -------------------------------------------------
distributed.core - INFO - Starting established connection
distributed.core - INFO - Event loop was unresponsive in Worker for 5.03s.  This is often caused by long-running GIL-holding functions or moving large chunks of data. This can cause timeouts and instability.
distributed.core - INFO - Event loop was unresponsive in Worker for 5.03s.  This is often caused by long-running GIL-holding functions or moving large chunks of data. This can cause timeouts and instability.
distributed.core - INFO - Event loop was unresponsive in Worker for 15.58s.  This is often caused by long-running GIL-holding functions or moving large chunks of data. This can cause timeouts and instability.
distributed.core - INFO - Event loop was unresponsive in Worker for 15.60s.  This is often caused by long-running GIL-holding functions or moving large chunks of data. This can cause timeouts and instability.
distributed.core - INFO - Event loop was unresponsive in Worker for 56.76s.  This is often caused by long-running GIL-holding functions or moving large chunks of data. This can cause timeouts and instability.
distributed.core - INFO - Event loop was unresponsive in Worker for 56.93s.  This is often caused by long-running GIL-holding functions or moving large chunks of data. This can cause timeouts and instability.
distributed.utils_perf - INFO - full garbage collection released 12.39 MB from 32 reference cycles (threshold: 10.00 MB)
distributed.core - INFO - Event loop was unresponsive in Worker for 15.11s.  This is often caused by long-running GIL-holding functions or moving large chunks of data. This can cause timeouts and instability.
distributed.core - INFO - Event loop was unresponsive in Worker for 15.72s.  This is often caused by long-running GIL-holding functions or moving large chunks of data. This can cause timeouts and instability.
distributed.worker - ERROR - Worker stream died during communication: tcp://10.148.0.144:60204
Traceback (most recent call last):
  File "/home1/datahome/xyu/.miniconda3/envs/equinox/lib/python3.6/site-packages/distributed/comm/core.py", line 186, in connect
    quiet_exceptions=EnvironmentError)
  File "/home1/datahome/xyu/.miniconda3/envs/equinox/lib/python3.6/site-packages/tornado/gen.py", line 1099, in run
    value = future.result()
tornado.util.TimeoutError: Timeout

During handling of the above exception, another exception occurred:

Traceback (most recent call last):
  File "/home1/datahome/xyu/.miniconda3/envs/equinox/lib/python3.6/site-packages/distributed/worker.py", line 1774, in gather_dep
    who=self.address)
  File "/home1/datahome/xyu/.miniconda3/envs/equinox/lib/python3.6/site-packages/tornado/gen.py", line 1099, in run
    value = future.result()
  File "/home1/datahome/xyu/.miniconda3/envs/equinox/lib/python3.6/site-packages/tornado/gen.py", line 1107, in run
    yielded = self.gen.throw(*exc_info)
  File "/home1/datahome/xyu/.miniconda3/envs/equinox/lib/python3.6/site-packages/distributed/core.py", line 608, in send_recv_from_rpc
    comm = yield self.pool.connect(self.addr)
  File "/home1/datahome/xyu/.miniconda3/envs/equinox/lib/python3.6/site-packages/tornado/gen.py", line 1099, in run
    value = future.result()
  File "/home1/datahome/xyu/.miniconda3/envs/equinox/lib/python3.6/site-packages/tornado/gen.py", line 1107, in run
    yielded = self.gen.throw(*exc_info)
  File "/home1/datahome/xyu/.miniconda3/envs/equinox/lib/python3.6/site-packages/distributed/core.py", line 719, in connect
    connection_args=self.connection_args)
  File "/home1/datahome/xyu/.miniconda3/envs/equinox/lib/python3.6/site-packages/tornado/gen.py", line 1099, in run
    value = future.result()
  File "/home1/datahome/xyu/.miniconda3/envs/equinox/lib/python3.6/site-packages/tornado/gen.py", line 1107, in run
    yielded = self.gen.throw(*exc_info)
  File "/home1/datahome/xyu/.miniconda3/envs/equinox/lib/python3.6/site-packages/distributed/comm/core.py", line 195, in connect
    _raise(error)
  File "/home1/datahome/xyu/.miniconda3/envs/equinox/lib/python3.6/site-packages/distributed/comm/core.py", line 178, in _raise
    raise IOError(msg)
OSError: Timed out trying to connect to 'tcp://10.148.0.144:60204' after 10 s: connect() didn't finish in time
distributed.worker - ERROR - Worker stream died during communication: tcp://10.148.0.72:52386
Traceback (most recent call last):
  File "/home1/datahome/xyu/.miniconda3/envs/equinox/lib/python3.6/site-packages/distributed/comm/core.py", line 186, in connect
    quiet_exceptions=EnvironmentError)
  File "/home1/datahome/xyu/.miniconda3/envs/equinox/lib/python3.6/site-packages/tornado/gen.py", line 1099, in run
    value = future.result()
tornado.util.TimeoutError: Timeout

During handling of the above exception, another exception occurred:

Traceback (most recent call last):
  File "/home1/datahome/xyu/.miniconda3/envs/equinox/lib/python3.6/site-packages/distributed/worker.py", line 1774, in gather_dep
    who=self.address)
  File "/home1/datahome/xyu/.miniconda3/envs/equinox/lib/python3.6/site-packages/tornado/gen.py", line 1099, in run
    value = future.result()
  File "/home1/datahome/xyu/.miniconda3/envs/equinox/lib/python3.6/site-packages/tornado/gen.py", line 1107, in run
    yielded = self.gen.throw(*exc_info)
  File "/home1/datahome/xyu/.miniconda3/envs/equinox/lib/python3.6/site-packages/distributed/core.py", line 608, in send_recv_from_rpc
    comm = yield self.pool.connect(self.addr)
  File "/home1/datahome/xyu/.miniconda3/envs/equinox/lib/python3.6/site-packages/tornado/gen.py", line 1099, in run
    value = future.result()
  File "/home1/datahome/xyu/.miniconda3/envs/equinox/lib/python3.6/site-packages/tornado/gen.py", line 1107, in run
    yielded = self.gen.throw(*exc_info)
  File "/home1/datahome/xyu/.miniconda3/envs/equinox/lib/python3.6/site-packages/distributed/core.py", line 719, in connect
    connection_args=self.connection_args)
  File "/home1/datahome/xyu/.miniconda3/envs/equinox/lib/python3.6/site-packages/tornado/gen.py", line 1099, in run
    value = future.result()
  File "/home1/datahome/xyu/.miniconda3/envs/equinox/lib/python3.6/site-packages/tornado/gen.py", line 1107, in run
    yielded = self.gen.throw(*exc_info)
  File "/home1/datahome/xyu/.miniconda3/envs/equinox/lib/python3.6/site-packages/distributed/comm/core.py", line 195, in connect
    _raise(error)
  File "/home1/datahome/xyu/.miniconda3/envs/equinox/lib/python3.6/site-packages/distributed/comm/core.py", line 178, in _raise
    raise IOError(msg)
OSError: Timed out trying to connect to 'tcp://10.148.0.72:52386' after 10 s: connect() didn't finish in time
distributed.worker - ERROR - Worker stream died during communication: tcp://10.148.0.73:36892
Traceback (most recent call last):
  File "/home1/datahome/xyu/.miniconda3/envs/equinox/lib/python3.6/site-packages/distributed/comm/core.py", line 186, in connect
    quiet_exceptions=EnvironmentError)
  File "/home1/datahome/xyu/.miniconda3/envs/equinox/lib/python3.6/site-packages/tornado/gen.py", line 1099, in run
    value = future.result()
tornado.util.TimeoutError: Timeout

During handling of the above exception, another exception occurred:

Traceback (most recent call last):
  File "/home1/datahome/xyu/.miniconda3/envs/equinox/lib/python3.6/site-packages/distributed/worker.py", line 1774, in gather_dep
    who=self.address)
  File "/home1/datahome/xyu/.miniconda3/envs/equinox/lib/python3.6/site-packages/tornado/gen.py", line 1099, in run
    value = future.result()
  File "/home1/datahome/xyu/.miniconda3/envs/equinox/lib/python3.6/site-packages/tornado/gen.py", line 1107, in run
    yielded = self.gen.throw(*exc_info)
  File "/home1/datahome/xyu/.miniconda3/envs/equinox/lib/python3.6/site-packages/distributed/core.py", line 608, in send_recv_from_rpc
    comm = yield self.pool.connect(self.addr)
  File "/home1/datahome/xyu/.miniconda3/envs/equinox/lib/python3.6/site-packages/tornado/gen.py", line 1099, in run
    value = future.result()
  File "/home1/datahome/xyu/.miniconda3/envs/equinox/lib/python3.6/site-packages/tornado/gen.py", line 1107, in run
    yielded = self.gen.throw(*exc_info)
  File "/home1/datahome/xyu/.miniconda3/envs/equinox/lib/python3.6/site-packages/distributed/core.py", line 719, in connect
    connection_args=self.connection_args)
  File "/home1/datahome/xyu/.miniconda3/envs/equinox/lib/python3.6/site-packages/tornado/gen.py", line 1099, in run
    value = future.result()
  File "/home1/datahome/xyu/.miniconda3/envs/equinox/lib/python3.6/site-packages/tornado/gen.py", line 1107, in run
    yielded = self.gen.throw(*exc_info)
  File "/home1/datahome/xyu/.miniconda3/envs/equinox/lib/python3.6/site-packages/distributed/comm/core.py", line 195, in connect
    _raise(error)
  File "/home1/datahome/xyu/.miniconda3/envs/equinox/lib/python3.6/site-packages/distributed/comm/core.py", line 178, in _raise
    raise IOError(msg)
OSError: Timed out trying to connect to 'tcp://10.148.0.73:36892' after 10 s: connect() didn't finish in time
distributed.worker - ERROR - Worker stream died during communication: tcp://10.148.1.1:48527
Traceback (most recent call last):
  File "/home1/datahome/xyu/.miniconda3/envs/equinox/lib/python3.6/site-packages/distributed/comm/core.py", line 186, in connect
    quiet_exceptions=EnvironmentError)
  File "/home1/datahome/xyu/.miniconda3/envs/equinox/lib/python3.6/site-packages/tornado/gen.py", line 1099, in run
    value = future.result()
tornado.util.TimeoutError: Timeout

During handling of the above exception, another exception occurred:

Traceback (most recent call last):
  File "/home1/datahome/xyu/.miniconda3/envs/equinox/lib/python3.6/site-packages/distributed/worker.py", line 1774, in gather_dep
    who=self.address)
  File "/home1/datahome/xyu/.miniconda3/envs/equinox/lib/python3.6/site-packages/tornado/gen.py", line 1099, in run
    value = future.result()
  File "/home1/datahome/xyu/.miniconda3/envs/equinox/lib/python3.6/site-packages/tornado/gen.py", line 1107, in run
    yielded = self.gen.throw(*exc_info)
  File "/home1/datahome/xyu/.miniconda3/envs/equinox/lib/python3.6/site-packages/distributed/core.py", line 608, in send_recv_from_rpc
    comm = yield self.pool.connect(self.addr)
  File "/home1/datahome/xyu/.miniconda3/envs/equinox/lib/python3.6/site-packages/tornado/gen.py", line 1099, in run
    value = future.result()
  File "/home1/datahome/xyu/.miniconda3/envs/equinox/lib/python3.6/site-packages/tornado/gen.py", line 1107, in run
    yielded = self.gen.throw(*exc_info)
  File "/home1/datahome/xyu/.miniconda3/envs/equinox/lib/python3.6/site-packages/distributed/core.py", line 719, in connect
    connection_args=self.connection_args)
  File "/home1/datahome/xyu/.miniconda3/envs/equinox/lib/python3.6/site-packages/tornado/gen.py", line 1099, in run
    value = future.result()
  File "/home1/datahome/xyu/.miniconda3/envs/equinox/lib/python3.6/site-packages/tornado/gen.py", line 1107, in run
    yielded = self.gen.throw(*exc_info)
  File "/home1/datahome/xyu/.miniconda3/envs/equinox/lib/python3.6/site-packages/distributed/comm/core.py", line 195, in connect
    _raise(error)
  File "/home1/datahome/xyu/.miniconda3/envs/equinox/lib/python3.6/site-packages/distributed/comm/core.py", line 178, in _raise
    raise IOError(msg)
OSError: Timed out trying to connect to 'tcp://10.148.1.1:48527' after 10 s: connect() didn't finish in time
distributed.worker - ERROR - Worker stream died during communication: tcp://10.148.0.73:52371
Traceback (most recent call last):
  File "/home1/datahome/xyu/.miniconda3/envs/equinox/lib/python3.6/site-packages/distributed/comm/core.py", line 186, in connect
    quiet_exceptions=EnvironmentError)
  File "/home1/datahome/xyu/.miniconda3/envs/equinox/lib/python3.6/site-packages/tornado/gen.py", line 1099, in run
    value = future.result()
tornado.util.TimeoutError: Timeout

During handling of the above exception, another exception occurred:

Traceback (most recent call last):
  File "/home1/datahome/xyu/.miniconda3/envs/equinox/lib/python3.6/site-packages/distributed/worker.py", line 1774, in gather_dep
    who=self.address)
  File "/home1/datahome/xyu/.miniconda3/envs/equinox/lib/python3.6/site-packages/tornado/gen.py", line 1099, in run
    value = future.result()
  File "/home1/datahome/xyu/.miniconda3/envs/equinox/lib/python3.6/site-packages/tornado/gen.py", line 1107, in run
    yielded = self.gen.throw(*exc_info)
  File "/home1/datahome/xyu/.miniconda3/envs/equinox/lib/python3.6/site-packages/distributed/core.py", line 608, in send_recv_from_rpc
    comm = yield self.pool.connect(self.addr)
  File "/home1/datahome/xyu/.miniconda3/envs/equinox/lib/python3.6/site-packages/tornado/gen.py", line 1099, in run
    value = future.result()
  File "/home1/datahome/xyu/.miniconda3/envs/equinox/lib/python3.6/site-packages/tornado/gen.py", line 1107, in run
    yielded = self.gen.throw(*exc_info)
  File "/home1/datahome/xyu/.miniconda3/envs/equinox/lib/python3.6/site-packages/distributed/core.py", line 719, in connect
    connection_args=self.connection_args)
  File "/home1/datahome/xyu/.miniconda3/envs/equinox/lib/python3.6/site-packages/tornado/gen.py", line 1099, in run
    value = future.result()
  File "/home1/datahome/xyu/.miniconda3/envs/equinox/lib/python3.6/site-packages/tornado/gen.py", line 1107, in run
    yielded = self.gen.throw(*exc_info)
  File "/home1/datahome/xyu/.miniconda3/envs/equinox/lib/python3.6/site-packages/distributed/comm/core.py", line 195, in connect
    _raise(error)
  File "/home1/datahome/xyu/.miniconda3/envs/equinox/lib/python3.6/site-packages/distributed/comm/core.py", line 178, in _raise
    raise IOError(msg)
OSError: Timed out trying to connect to 'tcp://10.148.0.73:52371' after 10 s: connect() didn't finish in time
distributed.worker - ERROR - Worker stream died during communication: tcp://10.148.0.193:51776
Traceback (most recent call last):
  File "/home1/datahome/xyu/.miniconda3/envs/equinox/lib/python3.6/site-packages/distributed/comm/core.py", line 186, in connect
    quiet_exceptions=EnvironmentError)
  File "/home1/datahome/xyu/.miniconda3/envs/equinox/lib/python3.6/site-packages/tornado/gen.py", line 1099, in run
    value = future.result()
tornado.util.TimeoutError: Timeout

During handling of the above exception, another exception occurred:

Traceback (most recent call last):
  File "/home1/datahome/xyu/.miniconda3/envs/equinox/lib/python3.6/site-packages/distributed/worker.py", line 1774, in gather_dep
    who=self.address)
  File "/home1/datahome/xyu/.miniconda3/envs/equinox/lib/python3.6/site-packages/tornado/gen.py", line 1099, in run
    value = future.result()
  File "/home1/datahome/xyu/.miniconda3/envs/equinox/lib/python3.6/site-packages/tornado/gen.py", line 1107, in run
    yielded = self.gen.throw(*exc_info)
  File "/home1/datahome/xyu/.miniconda3/envs/equinox/lib/python3.6/site-packages/distributed/core.py", line 608, in send_recv_from_rpc
    comm = yield self.pool.connect(self.addr)
  File "/home1/datahome/xyu/.miniconda3/envs/equinox/lib/python3.6/site-packages/tornado/gen.py", line 1099, in run
    value = future.result()
  File "/home1/datahome/xyu/.miniconda3/envs/equinox/lib/python3.6/site-packages/tornado/gen.py", line 1107, in run
    yielded = self.gen.throw(*exc_info)
  File "/home1/datahome/xyu/.miniconda3/envs/equinox/lib/python3.6/site-packages/distributed/core.py", line 719, in connect
    connection_args=self.connection_args)
  File "/home1/datahome/xyu/.miniconda3/envs/equinox/lib/python3.6/site-packages/tornado/gen.py", line 1099, in run
    value = future.result()
  File "/home1/datahome/xyu/.miniconda3/envs/equinox/lib/python3.6/site-packages/tornado/gen.py", line 1107, in run
    yielded = self.gen.throw(*exc_info)
  File "/home1/datahome/xyu/.miniconda3/envs/equinox/lib/python3.6/site-packages/distributed/comm/core.py", line 195, in connect
    _raise(error)
  File "/home1/datahome/xyu/.miniconda3/envs/equinox/lib/python3.6/site-packages/distributed/comm/core.py", line 178, in _raise
    raise IOError(msg)
OSError: Timed out trying to connect to 'tcp://10.148.0.193:51776' after 10 s: connect() didn't finish in time
distributed.worker - INFO - Can't find dependencies for key ('detrend-multiply-fftn-ff47af91f0a9399d975c9d8173d97c8c', 426, 4, 0)
distributed.worker - ERROR - Worker stream died during communication: tcp://10.148.0.252:48993
Traceback (most recent call last):
  File "/home1/datahome/xyu/.miniconda3/envs/equinox/lib/python3.6/site-packages/distributed/comm/core.py", line 186, in connect
    quiet_exceptions=EnvironmentError)
  File "/home1/datahome/xyu/.miniconda3/envs/equinox/lib/python3.6/site-packages/tornado/gen.py", line 1099, in run
    value = future.result()
tornado.util.TimeoutError: Timeout

During handling of the above exception, another exception occurred:

Traceback (most recent call last):
  File "/home1/datahome/xyu/.miniconda3/envs/equinox/lib/python3.6/site-packages/distributed/worker.py", line 1774, in gather_dep
    who=self.address)
  File "/home1/datahome/xyu/.miniconda3/envs/equinox/lib/python3.6/site-packages/tornado/gen.py", line 1099, in run
    value = future.result()
  File "/home1/datahome/xyu/.miniconda3/envs/equinox/lib/python3.6/site-packages/tornado/gen.py", line 1107, in run
    yielded = self.gen.throw(*exc_info)
  File "/home1/datahome/xyu/.miniconda3/envs/equinox/lib/python3.6/site-packages/distributed/core.py", line 608, in send_recv_from_rpc
    comm = yield self.pool.connect(self.addr)
  File "/home1/datahome/xyu/.miniconda3/envs/equinox/lib/python3.6/site-packages/tornado/gen.py", line 1099, in run
    value = future.result()
  File "/home1/datahome/xyu/.miniconda3/envs/equinox/lib/python3.6/site-packages/tornado/gen.py", line 1107, in run
    yielded = self.gen.throw(*exc_info)
  File "/home1/datahome/xyu/.miniconda3/envs/equinox/lib/python3.6/site-packages/distributed/core.py", line 719, in connect
    connection_args=self.connection_args)
  File "/home1/datahome/xyu/.miniconda3/envs/equinox/lib/python3.6/site-packages/tornado/gen.py", line 1099, in run
    value = future.result()
  File "/home1/datahome/xyu/.miniconda3/envs/equinox/lib/python3.6/site-packages/tornado/gen.py", line 1107, in run
    yielded = self.gen.throw(*exc_info)
  File "/home1/datahome/xyu/.miniconda3/envs/equinox/lib/python3.6/site-packages/distributed/comm/core.py", line 195, in connect
    _raise(error)
  File "/home1/datahome/xyu/.miniconda3/envs/equinox/lib/python3.6/site-packages/distributed/comm/core.py", line 178, in _raise
    raise IOError(msg)
OSError: Timed out trying to connect to 'tcp://10.148.0.252:48993' after 10 s: connect() didn't finish in time
distributed.worker - ERROR - Worker stream died during communication: tcp://10.148.0.136:35515
Traceback (most recent call last):
  File "/home1/datahome/xyu/.miniconda3/envs/equinox/lib/python3.6/site-packages/distributed/comm/core.py", line 186, in connect
    quiet_exceptions=EnvironmentError)
  File "/home1/datahome/xyu/.miniconda3/envs/equinox/lib/python3.6/site-packages/tornado/gen.py", line 1099, in run
    value = future.result()
tornado.util.TimeoutError: Timeout

During handling of the above exception, another exception occurred:

Traceback (most recent call last):
  File "/home1/datahome/xyu/.miniconda3/envs/equinox/lib/python3.6/site-packages/distributed/worker.py", line 1774, in gather_dep
    who=self.address)
  File "/home1/datahome/xyu/.miniconda3/envs/equinox/lib/python3.6/site-packages/tornado/gen.py", line 1099, in run
    value = future.result()
  File "/home1/datahome/xyu/.miniconda3/envs/equinox/lib/python3.6/site-packages/tornado/gen.py", line 1107, in run
    yielded = self.gen.throw(*exc_info)
  File "/home1/datahome/xyu/.miniconda3/envs/equinox/lib/python3.6/site-packages/distributed/core.py", line 608, in send_recv_from_rpc
    comm = yield self.pool.connect(self.addr)
  File "/home1/datahome/xyu/.miniconda3/envs/equinox/lib/python3.6/site-packages/tornado/gen.py", line 1099, in run
    value = future.result()
  File "/home1/datahome/xyu/.miniconda3/envs/equinox/lib/python3.6/site-packages/tornado/gen.py", line 1107, in run
    yielded = self.gen.throw(*exc_info)
  File "/home1/datahome/xyu/.miniconda3/envs/equinox/lib/python3.6/site-packages/distributed/core.py", line 719, in connect
    connection_args=self.connection_args)
  File "/home1/datahome/xyu/.miniconda3/envs/equinox/lib/python3.6/site-packages/tornado/gen.py", line 1099, in run
    value = future.result()
  File "/home1/datahome/xyu/.miniconda3/envs/equinox/lib/python3.6/site-packages/tornado/gen.py", line 1107, in run
    yielded = self.gen.throw(*exc_info)
  File "/home1/datahome/xyu/.miniconda3/envs/equinox/lib/python3.6/site-packages/distributed/comm/core.py", line 195, in connect
    _raise(error)
  File "/home1/datahome/xyu/.miniconda3/envs/equinox/lib/python3.6/site-packages/distributed/comm/core.py", line 178, in _raise
    raise IOError(msg)
OSError: Timed out trying to connect to 'tcp://10.148.0.136:35515' after 10 s: connect() didn't finish in time
distributed.worker - ERROR - Worker stream died during communication: tcp://10.148.0.144:33693
Traceback (most recent call last):
  File "/home1/datahome/xyu/.miniconda3/envs/equinox/lib/python3.6/site-packages/distributed/comm/core.py", line 186, in connect
    quiet_exceptions=EnvironmentError)
  File "/home1/datahome/xyu/.miniconda3/envs/equinox/lib/python3.6/site-packages/tornado/gen.py", line 1099, in run
    value = future.result()
tornado.util.TimeoutError: Timeout

During handling of the above exception, another exception occurred:

Traceback (most recent call last):
  File "/home1/datahome/xyu/.miniconda3/envs/equinox/lib/python3.6/site-packages/distributed/worker.py", line 1774, in gather_dep
    who=self.address)
  File "/home1/datahome/xyu/.miniconda3/envs/equinox/lib/python3.6/site-packages/tornado/gen.py", line 1099, in run
    value = future.result()
  File "/home1/datahome/xyu/.miniconda3/envs/equinox/lib/python3.6/site-packages/tornado/gen.py", line 1107, in run
    yielded = self.gen.throw(*exc_info)
  File "/home1/datahome/xyu/.miniconda3/envs/equinox/lib/python3.6/site-packages/distributed/core.py", line 608, in send_recv_from_rpc
    comm = yield self.pool.connect(self.addr)
  File "/home1/datahome/xyu/.miniconda3/envs/equinox/lib/python3.6/site-packages/tornado/gen.py", line 1099, in run
    value = future.result()
  File "/home1/datahome/xyu/.miniconda3/envs/equinox/lib/python3.6/site-packages/tornado/gen.py", line 1107, in run
    yielded = self.gen.throw(*exc_info)
  File "/home1/datahome/xyu/.miniconda3/envs/equinox/lib/python3.6/site-packages/distributed/core.py", line 719, in connect
    connection_args=self.connection_args)
  File "/home1/datahome/xyu/.miniconda3/envs/equinox/lib/python3.6/site-packages/tornado/gen.py", line 1099, in run
    value = future.result()
  File "/home1/datahome/xyu/.miniconda3/envs/equinox/lib/python3.6/site-packages/tornado/gen.py", line 1107, in run
    yielded = self.gen.throw(*exc_info)
  File "/home1/datahome/xyu/.miniconda3/envs/equinox/lib/python3.6/site-packages/distributed/comm/core.py", line 195, in connect
    _raise(error)
  File "/home1/datahome/xyu/.miniconda3/envs/equinox/lib/python3.6/site-packages/distributed/comm/core.py", line 178, in _raise
    raise IOError(msg)
OSError: Timed out trying to connect to 'tcp://10.148.0.144:33693' after 10 s: connect() didn't finish in time
distributed.worker - ERROR - Worker stream died during communication: tcp://10.148.0.146:51853
Traceback (most recent call last):
  File "/home1/datahome/xyu/.miniconda3/envs/equinox/lib/python3.6/site-packages/distributed/comm/core.py", line 186, in connect
    quiet_exceptions=EnvironmentError)
  File "/home1/datahome/xyu/.miniconda3/envs/equinox/lib/python3.6/site-packages/tornado/gen.py", line 1099, in run
    value = future.result()
tornado.util.TimeoutError: Timeout

During handling of the above exception, another exception occurred:

Traceback (most recent call last):
  File "/home1/datahome/xyu/.miniconda3/envs/equinox/lib/python3.6/site-packages/distributed/worker.py", line 1774, in gather_dep
    who=self.address)
  File "/home1/datahome/xyu/.miniconda3/envs/equinox/lib/python3.6/site-packages/tornado/gen.py", line 1099, in run
    value = future.result()
  File "/home1/datahome/xyu/.miniconda3/envs/equinox/lib/python3.6/site-packages/tornado/gen.py", line 1107, in run
    yielded = self.gen.throw(*exc_info)
  File "/home1/datahome/xyu/.miniconda3/envs/equinox/lib/python3.6/site-packages/distributed/core.py", line 608, in send_recv_from_rpc
    comm = yield self.pool.connect(self.addr)
  File "/home1/datahome/xyu/.miniconda3/envs/equinox/lib/python3.6/site-packages/tornado/gen.py", line 1099, in run
    value = future.result()
  File "/home1/datahome/xyu/.miniconda3/envs/equinox/lib/python3.6/site-packages/tornado/gen.py", line 1107, in run
    yielded = self.gen.throw(*exc_info)
  File "/home1/datahome/xyu/.miniconda3/envs/equinox/lib/python3.6/site-packages/distributed/core.py", line 719, in connect
    connection_args=self.connection_args)
  File "/home1/datahome/xyu/.miniconda3/envs/equinox/lib/python3.6/site-packages/tornado/gen.py", line 1099, in run
    value = future.result()
  File "/home1/datahome/xyu/.miniconda3/envs/equinox/lib/python3.6/site-packages/tornado/gen.py", line 1107, in run
    yielded = self.gen.throw(*exc_info)
  File "/home1/datahome/xyu/.miniconda3/envs/equinox/lib/python3.6/site-packages/distributed/comm/core.py", line 195, in connect
    _raise(error)
  File "/home1/datahome/xyu/.miniconda3/envs/equinox/lib/python3.6/site-packages/distributed/comm/core.py", line 178, in _raise
    raise IOError(msg)
OSError: Timed out trying to connect to 'tcp://10.148.0.146:51853' after 10 s: connect() didn't finish in time
distributed.worker - ERROR - Worker stream died during communication: tcp://10.148.0.202:34371
Traceback (most recent call last):
  File "/home1/datahome/xyu/.miniconda3/envs/equinox/lib/python3.6/site-packages/distributed/comm/core.py", line 186, in connect
    quiet_exceptions=EnvironmentError)
  File "/home1/datahome/xyu/.miniconda3/envs/equinox/lib/python3.6/site-packages/tornado/gen.py", line 1099, in run
    value = future.result()
tornado.util.TimeoutError: Timeout

During handling of the above exception, another exception occurred:

Traceback (most recent call last):
  File "/home1/datahome/xyu/.miniconda3/envs/equinox/lib/python3.6/site-packages/distributed/worker.py", line 1774, in gather_dep
    who=self.address)
  File "/home1/datahome/xyu/.miniconda3/envs/equinox/lib/python3.6/site-packages/tornado/gen.py", line 1099, in run
    value = future.result()
  File "/home1/datahome/xyu/.miniconda3/envs/equinox/lib/python3.6/site-packages/tornado/gen.py", line 1107, in run
    yielded = self.gen.throw(*exc_info)
  File "/home1/datahome/xyu/.miniconda3/envs/equinox/lib/python3.6/site-packages/distributed/core.py", line 608, in send_recv_from_rpc
    comm = yield self.pool.connect(self.addr)
  File "/home1/datahome/xyu/.miniconda3/envs/equinox/lib/python3.6/site-packages/tornado/gen.py", line 1099, in run
    value = future.result()
  File "/home1/datahome/xyu/.miniconda3/envs/equinox/lib/python3.6/site-packages/tornado/gen.py", line 1107, in run
    yielded = self.gen.throw(*exc_info)
  File "/home1/datahome/xyu/.miniconda3/envs/equinox/lib/python3.6/site-packages/distributed/core.py", line 719, in connect
    connection_args=self.connection_args)
  File "/home1/datahome/xyu/.miniconda3/envs/equinox/lib/python3.6/site-packages/tornado/gen.py", line 1099, in run
    value = future.result()
  File "/home1/datahome/xyu/.miniconda3/envs/equinox/lib/python3.6/site-packages/tornado/gen.py", line 1107, in run
    yielded = self.gen.throw(*exc_info)
  File "/home1/datahome/xyu/.miniconda3/envs/equinox/lib/python3.6/site-packages/distributed/comm/core.py", line 195, in connect
    _raise(error)
  File "/home1/datahome/xyu/.miniconda3/envs/equinox/lib/python3.6/site-packages/distributed/comm/core.py", line 178, in _raise
    raise IOError(msg)
OSError: Timed out trying to connect to 'tcp://10.148.0.202:34371' after 10 s: connect() didn't finish in time
distributed.worker - ERROR - Worker stream died during communication: tcp://10.148.1.18:55843
Traceback (most recent call last):
  File "/home1/datahome/xyu/.miniconda3/envs/equinox/lib/python3.6/site-packages/distributed/comm/core.py", line 186, in connect
    quiet_exceptions=EnvironmentError)
  File "/home1/datahome/xyu/.miniconda3/envs/equinox/lib/python3.6/site-packages/tornado/gen.py", line 1099, in run
    value = future.result()
tornado.util.TimeoutError: Timeout

During handling of the above exception, another exception occurred:

Traceback (most recent call last):
  File "/home1/datahome/xyu/.miniconda3/envs/equinox/lib/python3.6/site-packages/distributed/worker.py", line 1774, in gather_dep
    who=self.address)
  File "/home1/datahome/xyu/.miniconda3/envs/equinox/lib/python3.6/site-packages/tornado/gen.py", line 1099, in run
    value = future.result()
  File "/home1/datahome/xyu/.miniconda3/envs/equinox/lib/python3.6/site-packages/tornado/gen.py", line 1107, in run
    yielded = self.gen.throw(*exc_info)
  File "/home1/datahome/xyu/.miniconda3/envs/equinox/lib/python3.6/site-packages/distributed/core.py", line 608, in send_recv_from_rpc
    comm = yield self.pool.connect(self.addr)
  File "/home1/datahome/xyu/.miniconda3/envs/equinox/lib/python3.6/site-packages/tornado/gen.py", line 1099, in run
    value = future.result()
  File "/home1/datahome/xyu/.miniconda3/envs/equinox/lib/python3.6/site-packages/tornado/gen.py", line 1107, in run
    yielded = self.gen.throw(*exc_info)
  File "/home1/datahome/xyu/.miniconda3/envs/equinox/lib/python3.6/site-packages/distributed/core.py", line 719, in connect
    connection_args=self.connection_args)
  File "/home1/datahome/xyu/.miniconda3/envs/equinox/lib/python3.6/site-packages/tornado/gen.py", line 1099, in run
    value = future.result()
  File "/home1/datahome/xyu/.miniconda3/envs/equinox/lib/python3.6/site-packages/tornado/gen.py", line 1107, in run
    yielded = self.gen.throw(*exc_info)
  File "/home1/datahome/xyu/.miniconda3/envs/equinox/lib/python3.6/site-packages/distributed/comm/core.py", line 195, in connect
    _raise(error)
  File "/home1/datahome/xyu/.miniconda3/envs/equinox/lib/python3.6/site-packages/distributed/comm/core.py", line 178, in _raise
    raise IOError(msg)
OSError: Timed out trying to connect to 'tcp://10.148.1.18:55843' after 10 s: connect() didn't finish in time
distributed.worker - ERROR - Worker stream died during communication: tcp://10.148.0.193:36790
Traceback (most recent call last):
  File "/home1/datahome/xyu/.miniconda3/envs/equinox/lib/python3.6/site-packages/distributed/comm/core.py", line 186, in connect
    quiet_exceptions=EnvironmentError)
  File "/home1/datahome/xyu/.miniconda3/envs/equinox/lib/python3.6/site-packages/tornado/gen.py", line 1099, in run
    value = future.result()
tornado.util.TimeoutError: Timeout

During handling of the above exception, another exception occurred:

Traceback (most recent call last):
  File "/home1/datahome/xyu/.miniconda3/envs/equinox/lib/python3.6/site-packages/distributed/worker.py", line 1774, in gather_dep
    who=self.address)
  File "/home1/datahome/xyu/.miniconda3/envs/equinox/lib/python3.6/site-packages/tornado/gen.py", line 1099, in run
    value = future.result()
  File "/home1/datahome/xyu/.miniconda3/envs/equinox/lib/python3.6/site-packages/tornado/gen.py", line 1107, in run
    yielded = self.gen.throw(*exc_info)
  File "/home1/datahome/xyu/.miniconda3/envs/equinox/lib/python3.6/site-packages/distributed/core.py", line 608, in send_recv_from_rpc
    comm = yield self.pool.connect(self.addr)
  File "/home1/datahome/xyu/.miniconda3/envs/equinox/lib/python3.6/site-packages/tornado/gen.py", line 1099, in run
    value = future.result()
  File "/home1/datahome/xyu/.miniconda3/envs/equinox/lib/python3.6/site-packages/tornado/gen.py", line 1107, in run
    yielded = self.gen.throw(*exc_info)
  File "/home1/datahome/xyu/.miniconda3/envs/equinox/lib/python3.6/site-packages/distributed/core.py", line 719, in connect
    connection_args=self.connection_args)
  File "/home1/datahome/xyu/.miniconda3/envs/equinox/lib/python3.6/site-packages/tornado/gen.py", line 1099, in run
    value = future.result()
  File "/home1/datahome/xyu/.miniconda3/envs/equinox/lib/python3.6/site-packages/tornado/gen.py", line 1107, in run
    yielded = self.gen.throw(*exc_info)
  File "/home1/datahome/xyu/.miniconda3/envs/equinox/lib/python3.6/site-packages/distributed/comm/core.py", line 195, in connect
    _raise(error)
  File "/home1/datahome/xyu/.miniconda3/envs/equinox/lib/python3.6/site-packages/distributed/comm/core.py", line 178, in _raise
    raise IOError(msg)
OSError: Timed out trying to connect to 'tcp://10.148.0.193:36790' after 10 s: connect() didn't finish in time
distributed.worker - ERROR - Worker stream died during communication: tcp://10.148.1.17:35417
Traceback (most recent call last):
  File "/home1/datahome/xyu/.miniconda3/envs/equinox/lib/python3.6/site-packages/distributed/comm/core.py", line 186, in connect
    quiet_exceptions=EnvironmentError)
  File "/home1/datahome/xyu/.miniconda3/envs/equinox/lib/python3.6/site-packages/tornado/gen.py", line 1099, in run
    value = future.result()
tornado.util.TimeoutError: Timeout

During handling of the above exception, another exception occurred:

Traceback (most recent call last):
  File "/home1/datahome/xyu/.miniconda3/envs/equinox/lib/python3.6/site-packages/distributed/worker.py", line 1774, in gather_dep
    who=self.address)
  File "/home1/datahome/xyu/.miniconda3/envs/equinox/lib/python3.6/site-packages/tornado/gen.py", line 1099, in run
    value = future.result()
  File "/home1/datahome/xyu/.miniconda3/envs/equinox/lib/python3.6/site-packages/tornado/gen.py", line 1107, in run
    yielded = self.gen.throw(*exc_info)
  File "/home1/datahome/xyu/.miniconda3/envs/equinox/lib/python3.6/site-packages/distributed/core.py", line 608, in send_recv_from_rpc
    comm = yield self.pool.connect(self.addr)
  File "/home1/datahome/xyu/.miniconda3/envs/equinox/lib/python3.6/site-packages/tornado/gen.py", line 1099, in run
    value = future.result()
  File "/home1/datahome/xyu/.miniconda3/envs/equinox/lib/python3.6/site-packages/tornado/gen.py", line 1107, in run
    yielded = self.gen.throw(*exc_info)
  File "/home1/datahome/xyu/.miniconda3/envs/equinox/lib/python3.6/site-packages/distributed/core.py", line 719, in connect
    connection_args=self.connection_args)
  File "/home1/datahome/xyu/.miniconda3/envs/equinox/lib/python3.6/site-packages/tornado/gen.py", line 1099, in run
    value = future.result()
  File "/home1/datahome/xyu/.miniconda3/envs/equinox/lib/python3.6/site-packages/tornado/gen.py", line 1107, in run
    yielded = self.gen.throw(*exc_info)
  File "/home1/datahome/xyu/.miniconda3/envs/equinox/lib/python3.6/site-packages/distributed/comm/core.py", line 195, in connect
    _raise(error)
  File "/home1/datahome/xyu/.miniconda3/envs/equinox/lib/python3.6/site-packages/distributed/comm/core.py", line 178, in _raise
    raise IOError(msg)
OSError: Timed out trying to connect to 'tcp://10.148.1.17:35417' after 10 s: connect() didn't finish in time
distributed.worker - ERROR - Worker stream died during communication: tcp://10.148.0.212:60898
Traceback (most recent call last):
  File "/home1/datahome/xyu/.miniconda3/envs/equinox/lib/python3.6/site-packages/distributed/comm/core.py", line 186, in connect
    quiet_exceptions=EnvironmentError)
  File "/home1/datahome/xyu/.miniconda3/envs/equinox/lib/python3.6/site-packages/tornado/gen.py", line 1099, in run
    value = future.result()
tornado.util.TimeoutError: Timeout

During handling of the above exception, another exception occurred:

Traceback (most recent call last):
  File "/home1/datahome/xyu/.miniconda3/envs/equinox/lib/python3.6/site-packages/distributed/worker.py", line 1774, in gather_dep
    who=self.address)
  File "/home1/datahome/xyu/.miniconda3/envs/equinox/lib/python3.6/site-packages/tornado/gen.py", line 1099, in run
    value = future.result()
  File "/home1/datahome/xyu/.miniconda3/envs/equinox/lib/python3.6/site-packages/tornado/gen.py", line 1107, in run
    yielded = self.gen.throw(*exc_info)
  File "/home1/datahome/xyu/.miniconda3/envs/equinox/lib/python3.6/site-packages/distributed/core.py", line 608, in send_recv_from_rpc
    comm = yield self.pool.connect(self.addr)
  File "/home1/datahome/xyu/.miniconda3/envs/equinox/lib/python3.6/site-packages/tornado/gen.py", line 1099, in run
    value = future.result()
  File "/home1/datahome/xyu/.miniconda3/envs/equinox/lib/python3.6/site-packages/tornado/gen.py", line 1107, in run
    yielded = self.gen.throw(*exc_info)
  File "/home1/datahome/xyu/.miniconda3/envs/equinox/lib/python3.6/site-packages/distributed/core.py", line 719, in connect
    connection_args=self.connection_args)
  File "/home1/datahome/xyu/.miniconda3/envs/equinox/lib/python3.6/site-packages/tornado/gen.py", line 1099, in run
    value = future.result()
  File "/home1/datahome/xyu/.miniconda3/envs/equinox/lib/python3.6/site-packages/tornado/gen.py", line 1107, in run
    yielded = self.gen.throw(*exc_info)
  File "/home1/datahome/xyu/.miniconda3/envs/equinox/lib/python3.6/site-packages/distributed/comm/core.py", line 195, in connect
    _raise(error)
  File "/home1/datahome/xyu/.miniconda3/envs/equinox/lib/python3.6/site-packages/distributed/comm/core.py", line 178, in _raise
    raise IOError(msg)
OSError: Timed out trying to connect to 'tcp://10.148.0.212:60898' after 10 s: connect() didn't finish in time
distributed.worker - INFO - Dependent not found: ('where-df72cf21e168d64356411fd221dff700', 426, 4, 0) 0 .  Asking scheduler
distributed.utils_perf - INFO - full garbage collection released 12.73 MB from 64906 reference cycles (threshold: 10.00 MB)
/home1/datahome/xyu/.miniconda3/envs/equinox/lib/python3.6/site-packages/dask/array/chunk.py:228: ComplexWarning: Casting complex values to real discards the imaginary part
  return x.astype(astype_dtype, **kwargs)
distributed.utils_perf - INFO - full garbage collection released 19.08 MB from 129858 reference cycles (threshold: 10.00 MB)
/home1/datahome/xyu/.miniconda3/envs/equinox/lib/python3.6/site-packages/dask/array/chunk.py:228: ComplexWarning: Casting complex values to real discards the imaginary part
  return x.astype(astype_dtype, **kwargs)
distributed.utils_perf - INFO - full garbage collection released 10.96 MB from 64875 reference cycles (threshold: 10.00 MB)
distributed.utils_perf - INFO - full garbage collection released 27.34 MB from 194553 reference cycles (threshold: 10.00 MB)
distributed.utils_perf - INFO - full garbage collection released 19.95 MB from 194730 reference cycles (threshold: 10.00 MB)
distributed.utils_perf - INFO - full garbage collection released 13.57 MB from 64910 reference cycles (threshold: 10.00 MB)
distributed.utils_perf - INFO - full garbage collection released 13.58 MB from 64885 reference cycles (threshold: 10.00 MB)
distributed.utils_perf - INFO - full garbage collection released 49.14 MB from 129786 reference cycles (threshold: 10.00 MB)
distributed.utils_perf - INFO - full garbage collection released 11.16 MB from 64920 reference cycles (threshold: 10.00 MB)
distributed.utils_perf - INFO - full garbage collection released 10.30 MB from 64925 reference cycles (threshold: 10.00 MB)
distributed.utils_perf - INFO - full garbage collection released 11.18 MB from 64876 reference cycles (threshold: 10.00 MB)
distributed.utils_perf - INFO - full garbage collection released 109.74 MB from 64943 reference cycles (threshold: 10.00 MB)
distributed.utils_perf - INFO - full garbage collection released 33.21 MB from 194557 reference cycles (threshold: 10.00 MB)
distributed.utils_perf - INFO - full garbage collection released 134.01 MB from 195108 reference cycles (threshold: 10.00 MB)
distributed.worker - INFO - Stopping worker at tcp://10.148.0.199:60457
distributed.worker - INFO - Stopping worker at tcp://10.148.0.199:49758
distributed.worker - INFO - Connection to scheduler broken.  Reconnecting...
distributed.worker - INFO - -------------------------------------------------
distributed.worker - INFO - Connection to scheduler broken.  Reconnecting...
distributed.worker - INFO - -------------------------------------------------
distributed.nanny - INFO - Closing Nanny at 'tcp://10.148.0.199:33773'
distributed.nanny - INFO - Closing Nanny at 'tcp://10.148.0.199:41876'
distributed.dask_worker - INFO - End worker
/home1/datahome/xyu/.miniconda3/envs/equinox/lib/python3.6/site-packages/distributed/utils.py:128: RuntimeWarning: Couldn't detect a suitable IP address for reaching '8.8.8.8', defaulting to '127.0.0.1': [Errno 101] Network is unreachable
  % (host, default, e), RuntimeWarning)
