Warning: no access to tty (Bad file descriptor).
Thus no job control in this shell.
/home1/datahome/xyu/.miniconda3/envs/equinox/lib/python3.6/site-packages/distributed/utils.py:128: RuntimeWarning: Couldn't detect a suitable IP address for reaching '8.8.8.8', defaulting to '127.0.0.1': [Errno 101] Network is unreachable
  % (host, default, e), RuntimeWarning)
distributed.nanny - INFO -         Start Nanny at: 'tcp://10.148.0.221:53109'
distributed.nanny - INFO -         Start Nanny at: 'tcp://10.148.0.221:55148'
/home1/datahome/xyu/.miniconda3/envs/equinox/lib/python3.6/site-packages/distributed/utils.py:128: RuntimeWarning: Couldn't detect a suitable IP address for reaching '8.8.8.8', defaulting to '127.0.0.1': [Errno 101] Network is unreachable
  % (host, default, e), RuntimeWarning)
distributed.worker - INFO -       Start worker at:   tcp://10.148.0.221:56172
distributed.worker - INFO -          Listening to:   tcp://10.148.0.221:56172
distributed.worker - INFO -              nanny at:         10.148.0.221:53109
distributed.worker - INFO -              bokeh at:          10.148.0.221:8789
distributed.worker - INFO - Waiting to connect to:     tcp://10.148.1.6:37872
distributed.worker - INFO - -------------------------------------------------
distributed.worker - INFO -               Threads:                          4
distributed.worker - INFO -                Memory:                   50.00 GB
distributed.worker - INFO -       Local Directory: /dev/shm/pbs.1460607.datarmor0/worker-dwks86qz
distributed.worker - INFO - -------------------------------------------------
distributed.worker - INFO -         Registered to:     tcp://10.148.1.6:37872
distributed.worker - INFO - -------------------------------------------------
distributed.core - INFO - Starting established connection
/home1/datahome/xyu/.miniconda3/envs/equinox/lib/python3.6/site-packages/distributed/utils.py:128: RuntimeWarning: Couldn't detect a suitable IP address for reaching '8.8.8.8', defaulting to '127.0.0.1': [Errno 101] Network is unreachable
  % (host, default, e), RuntimeWarning)
distributed.worker - INFO -       Start worker at:   tcp://10.148.0.221:51812
distributed.worker - INFO -          Listening to:   tcp://10.148.0.221:51812
distributed.worker - INFO -              nanny at:         10.148.0.221:55148
distributed.worker - INFO -              bokeh at:         10.148.0.221:49965
distributed.worker - INFO - Waiting to connect to:     tcp://10.148.1.6:37872
distributed.worker - INFO - -------------------------------------------------
distributed.worker - INFO -               Threads:                          4
distributed.worker - INFO -                Memory:                   50.00 GB
distributed.worker - INFO -       Local Directory: /dev/shm/pbs.1460607.datarmor0/worker-6xjhpzq6
distributed.worker - INFO - -------------------------------------------------
distributed.worker - INFO -         Registered to:     tcp://10.148.1.6:37872
distributed.worker - INFO - -------------------------------------------------
distributed.core - INFO - Starting established connection
Terminated
distributed.dask_worker - INFO - Exiting on signal 15
distributed.nanny - INFO - Closing Nanny at 'tcp://10.148.0.221:53109'
distributed.nanny - INFO - Closing Nanny at 'tcp://10.148.0.221:55148'
distributed.nanny - WARNING - Worker process 14390 was killed by unknown signal
distributed.nanny - WARNING - Worker process 14391 was killed by unknown signal
distributed.dask_worker - INFO - End worker
Traceback (most recent call last):
  File "/home1/datahome/xyu/.miniconda3/envs/equinox/lib/python3.6/multiprocessing/queues.py", line 240, in _feed
    send_bytes(obj)
  File "/home1/datahome/xyu/.miniconda3/envs/equinox/lib/python3.6/multiprocessing/connection.py", line 200, in send_bytes
    self._send_bytes(m[offset:offset + size])
  File "/home1/datahome/xyu/.miniconda3/envs/equinox/lib/python3.6/multiprocessing/connection.py", line 404, in _send_bytes
    self._send(header + buf)
  File "/home1/datahome/xyu/.miniconda3/envs/equinox/lib/python3.6/multiprocessing/connection.py", line 368, in _send
    n = write(self._handle, buf)
BrokenPipeError: [Errno 32] Broken pipe
Traceback (most recent call last):
  File "/home1/datahome/xyu/.miniconda3/envs/equinox/lib/python3.6/multiprocessing/queues.py", line 240, in _feed
    send_bytes(obj)
  File "/home1/datahome/xyu/.miniconda3/envs/equinox/lib/python3.6/multiprocessing/connection.py", line 200, in send_bytes
    self._send_bytes(m[offset:offset + size])
  File "/home1/datahome/xyu/.miniconda3/envs/equinox/lib/python3.6/multiprocessing/connection.py", line 404, in _send_bytes
    self._send(header + buf)
  File "/home1/datahome/xyu/.miniconda3/envs/equinox/lib/python3.6/multiprocessing/connection.py", line 368, in _send
    n = write(self._handle, buf)
BrokenPipeError: [Errno 32] Broken pipe
