Warning: no access to tty (Bad file descriptor).
Thus no job control in this shell.
/home1/datahome/xyu/.miniconda3/envs/equinox/lib/python3.6/site-packages/distributed/utils.py:128: RuntimeWarning: Couldn't detect a suitable IP address for reaching '8.8.8.8', defaulting to '127.0.0.1': [Errno 101] Network is unreachable
  % (host, default, e), RuntimeWarning)
distributed.nanny - INFO -         Start Nanny at: 'tcp://10.148.0.254:40078'
distributed.nanny - INFO -         Start Nanny at: 'tcp://10.148.0.254:33958'
/home1/datahome/xyu/.miniconda3/envs/equinox/lib/python3.6/site-packages/distributed/utils.py:128: RuntimeWarning: Couldn't detect a suitable IP address for reaching '8.8.8.8', defaulting to '127.0.0.1': [Errno 101] Network is unreachable
  % (host, default, e), RuntimeWarning)
distributed.worker - INFO -       Start worker at:   tcp://10.148.0.254:51366
distributed.worker - INFO -          Listening to:   tcp://10.148.0.254:51366
distributed.worker - INFO -              nanny at:         10.148.0.254:40078
distributed.worker - INFO -              bokeh at:          10.148.0.254:8789
distributed.worker - INFO - Waiting to connect to:   tcp://10.148.0.147:38716
distributed.worker - INFO - -------------------------------------------------
distributed.worker - INFO -               Threads:                          4
distributed.worker - INFO -                Memory:                   50.00 GB
distributed.worker - INFO -       Local Directory: /dev/shm/pbs.4524881.datarmor0/worker-nrwa5ppp
distributed.worker - INFO - -------------------------------------------------
distributed.worker - INFO -         Registered to:   tcp://10.148.0.147:38716
distributed.worker - INFO - -------------------------------------------------
distributed.core - INFO - Starting established connection
/home1/datahome/xyu/.miniconda3/envs/equinox/lib/python3.6/site-packages/distributed/utils.py:128: RuntimeWarning: Couldn't detect a suitable IP address for reaching '8.8.8.8', defaulting to '127.0.0.1': [Errno 101] Network is unreachable
  % (host, default, e), RuntimeWarning)
distributed.worker - INFO -       Start worker at:   tcp://10.148.0.254:40296
distributed.worker - INFO -          Listening to:   tcp://10.148.0.254:40296
distributed.worker - INFO -              nanny at:         10.148.0.254:33958
distributed.worker - INFO -              bokeh at:         10.148.0.254:42416
distributed.worker - INFO - Waiting to connect to:   tcp://10.148.0.147:38716
distributed.worker - INFO - -------------------------------------------------
distributed.worker - INFO -               Threads:                          4
distributed.worker - INFO -                Memory:                   50.00 GB
distributed.worker - INFO -       Local Directory: /dev/shm/pbs.4524881.datarmor0/worker-oawfd1k0
distributed.worker - INFO - -------------------------------------------------
distributed.worker - INFO -         Registered to:   tcp://10.148.0.147:38716
distributed.worker - INFO - -------------------------------------------------
distributed.core - INFO - Starting established connection
/home1/datahome/xyu/.miniconda3/envs/equinox/lib/python3.6/importlib/_bootstrap.py:219: RuntimeWarning: numpy.dtype size changed, may indicate binary incompatibility. Expected 96, got 88
  return f(*args, **kwds)
/home1/datahome/xyu/.miniconda3/envs/equinox/lib/python3.6/importlib/_bootstrap.py:219: RuntimeWarning: numpy.dtype size changed, may indicate binary incompatibility. Expected 96, got 88
  return f(*args, **kwds)
distributed.core - INFO - Event loop was unresponsive in Worker for 9.23s.  This is often caused by long-running GIL-holding functions or moving large chunks of data. This can cause timeouts and instability.
/home1/datahome/xyu/.miniconda3/envs/equinox/lib/python3.6/importlib/_bootstrap.py:219: RuntimeWarning: numpy.dtype size changed, may indicate binary incompatibility. Expected 96, got 88
  return f(*args, **kwds)
/home1/datahome/xyu/.miniconda3/envs/equinox/lib/python3.6/importlib/_bootstrap.py:219: RuntimeWarning: numpy.dtype size changed, may indicate binary incompatibility. Expected 96, got 88
  return f(*args, **kwds)
distributed.core - INFO - Event loop was unresponsive in Worker for 9.32s.  This is often caused by long-running GIL-holding functions or moving large chunks of data. This can cause timeouts and instability.
distributed.core - INFO - Event loop was unresponsive in Worker for 20.26s.  This is often caused by long-running GIL-holding functions or moving large chunks of data. This can cause timeouts and instability.
distributed.core - INFO - Event loop was unresponsive in Worker for 20.26s.  This is often caused by long-running GIL-holding functions or moving large chunks of data. This can cause timeouts and instability.
distributed.worker - INFO - Stopping worker at tcp://10.148.0.254:51366
distributed.worker - INFO - Stopping worker at tcp://10.148.0.254:40296
distributed.worker - INFO - Connection to scheduler broken.  Reconnecting...
distributed.worker - INFO - -------------------------------------------------
distributed.worker - INFO - Connection to scheduler broken.  Reconnecting...
distributed.worker - INFO - -------------------------------------------------
distributed.nanny - INFO - Closing Nanny at 'tcp://10.148.0.254:40078'
distributed.nanny - INFO - Closing Nanny at 'tcp://10.148.0.254:33958'
distributed.dask_worker - INFO - End worker
/home1/datahome/xyu/.miniconda3/envs/equinox/lib/python3.6/site-packages/distributed/utils.py:128: RuntimeWarning: Couldn't detect a suitable IP address for reaching '8.8.8.8', defaulting to '127.0.0.1': [Errno 101] Network is unreachable
  % (host, default, e), RuntimeWarning)
